<?xml version="1.0"?>
<robot xmlns:xacro="http://www.ros.org/wiki/xacro" name="agv1">

  <link name="base_footprint" />

  <joint name="base_joint" type="fixed">
    <parent link="base_footprint" />
    <child link="base_link" />
    <origin xyz="0 0 0.1" rpy="0 0 0" />
  </joint>

  <link name="base_link">
    <inertial>
      <origin xyz="0 0 0.89" rpy="0 0 0" />
      <mass value="2522.3" />
      <inertia ixx="990" ixy="0" ixz="0" iyy="990" iyz="0" izz="990" />
    </inertial>
    <visual>
      <origin xyz="0 0 0" rpy="0 0 1.574" />
      <geometry>
        <mesh filename="package://agv_sim/meshes/BODY_N_MAST.stl" scale="0.001 0.001 0.001" />
      </geometry>
      <material name="orange" />
    </visual>
    <collision>
      <origin xyz="0 0 0" rpy="0 0 1.574" />
      <geometry>
        <mesh filename="package://agv_sim/meshes/BODY_N_MAST.stl" scale="0.001 0.001 0.001" />
      </geometry>
    </collision>
  </link>

  <joint name="fork_joint" type="prismatic">
    <parent link="base_link" />
    <child link="fork_house" />
    <axis xyz="0 0 1"/>
    <limit lower="-0.05" upper="1.5" effort="1000.0" velocity="0.1"/>
    <origin xyz="-0.989 0 0.1" rpy="0 0 1.574" />
  </joint>

  <link name="fork_house">
    <inertial>
      <mass value="0.1"/>
      <inertia ixx="0.0" ixy="0.0" ixz="0.0" iyy="0.0" iyz="0.0" izz="0.0"/>
      <!-- <inertia ixx="320.5" ixy="0" ixz="0" iyy="34.5" iyz="0" izz="320.5"/> -->
    </inertial>
    <visual>
      <origin xyz="0 0 0" rpy="0 0 0" />
      <geometry>
        <mesh filename="package://agv_sim/meshes/FORK_HOUSE_RE.stl" scale = "0.001 0.001 0.001" />
      </geometry>
      <material name="dark_grey" />
    </visual>
    <collision>
      <origin xyz="0 0 0" rpy="0 0 0" />
      <geometry>
        <mesh filename="package://agv_sim/meshes/FORK_HOUSE_RE.stl" scale = "0.001 0.001 0.001" />
      </geometry>
    </collision>
  </link>

  <joint name="steering_joint" type="continuous">
    <parent link="base_link" />
    <child link="steering_part" />
    <origin xyz="0.216 0 0.334" rpy="0 0 1.574" />
    <!-- 0.212 -0.0476 0.344 -->
    <axis xyz="0 0 1" />
  </joint>


  <link name="steering_part">
    <inertial>
      <mass value="85.056" />
      <inertia ixx="2.81" ixy="0.0" ixz="-0.11" iyy="2.77" iyz="0.12" izz="0.9" />
    </inertial>
    <visual>
      <origin xyz="0 0 0" rpy="0 0 0" />
      <geometry>
        <mesh filename="package://agv_sim/meshes/STEERING_PART_RE2.stl" scale="0.001 0.001 0.001" />
      </geometry>
      <material name="white" />
    </visual>
    <collision>
      <origin xyz="0 0 0" rpy="0 0 0" />
      <geometry>
        <mesh filename="package://agv_sim/meshes/STEERING_PART_RE2.stl" scale="0.001 0.001 0.001" />
      </geometry>
    </collision>
  </link>

  <joint name="drive_wheel_joint" type="continuous">
    <parent link="steering_part" />
    <child link="drive_wheel" />
    <!-- <origin xyz="0.063 0.012 -0.285" rpy="0 0 0" /> -->
    <origin xyz="0.01 0.0 -0.285" rpy="0 0 0" />
    <axis xyz="1 0 0" />
  </joint>

  <link name="drive_wheel">
    <inertial>
      <mass value="21.755" />
      <inertia ixx="0.166" ixy="0.0" ixz="0.0" iyy="0.166" iyz="0.0" izz="0.166" />
    </inertial>
    <visual>
      <origin xyz="0 0 0" rpy="0 0 0" />
      <geometry>
        <mesh filename="package://agv_sim/meshes/DRIVE_WHEEL_RE2.stl" />
      </geometry>
      <material name="blue" />
    </visual>
    <collision>
      <origin xyz="0 0 0" rpy="0 0 0" />
      <geometry>
        <mesh filename="package://agv_sim/meshes/DRIVE_WHEEL_RE2.stl" />
      </geometry>
    </collision>
  </link>

  <joint name="front_wheel_l_joint" type="continuous">
    <parent link="base_link" />
    <child link="front_wheel_l" />
    <origin xyz="-0.86 -0.451 0.025" rpy="0 0 0" />
    <axis xyz="0 1 0" />
  </joint>

  <link name="front_wheel_l">
    <inertial>
      <mass value="16.096" />
      <inertia ixx="0.066" ixy="0.0" ixz="0.0" iyy="0.066" iyz="0.0" izz="0.066" />
    </inertial>
    <visual>
      <origin xyz="0 0 0" rpy="0 0 0" />
      <geometry>
        <mesh filename="package://agv_sim/meshes/FRONT_WHEEL_RE2.stl" />
      </geometry>
      <material name="green" />
    </visual>
    <collision>
      <origin xyz="0 0 0" rpy="0 0 0" />
      <geometry>
        <mesh filename="package://agv_sim/meshes/FRONT_WHEEL_RE2.stl" />
      </geometry>
    </collision>
  </link>

  <joint name="front_wheel_r_joint" type="continuous">
    <parent link="base_link" />
    <child link="front_wheel_r" />
    <origin xyz="-0.86 0.451 0.025" rpy="0 0 3.14" />
    <axis xyz="0 1 0" />
  </joint>

  <link name="front_wheel_r">
    <inertial>
      <mass value="16.096" />
      <inertia ixx="0.066" ixy="0.0" ixz="0.0" iyy="0.066" iyz="0.0" izz="0.066" />
    </inertial>
    <visual>
      <origin xyz="0 0 0" rpy="0 0 0" />
      <geometry>
        <mesh filename="package://agv_sim/meshes/FRONT_WHEEL_RE2.stl" />
      </geometry>
      <material name="green" />
    </visual>
    <collision>
      <origin xyz="0 0 0" rpy="0 0 0" />
      <geometry>
        <mesh filename="package://agv_sim/meshes/FRONT_WHEEL_RE2.stl" />
      </geometry>
    </collision>
  </link>

  <joint name="imu_joint" type="fixed">
    <parent link="base_link" />
    <child link="imu_link" />
    <origin xyz="-0.341 0.103 0.763" rpy="0 0 0" />
  </joint>

  <link name="imu_link">
    <!-- <inertial>
      <mass value="0.641"/>
      <inertia ixx="0.001" ixy="0.0" ixz="0.0" iyy="0.001" iyz="0.0" izz="0.002"/>
    </inertial>
    <visual>
      <origin xyz="0 0 0" rpy="0 0 0" />
      <geometry>
        <mesh filename="package://agv_sim/meshes/IMU.stl" scale = "0.001 0.001 0.001"/>
      </geometry>
    </visual> -->
  </link>

  <joint name="slam_lidar_joint" type="fixed">
    <parent link="base_link" />
    <child link="slam_lidar" />
    <origin xyz="0 -0.2 2.197" rpy="0 0 0" />
  </joint>

  <link name="slam_lidar">
    <inertial>
      <mass value="0.641" />
      <inertia ixx="0.001" ixy="0.0" ixz="0.0" iyy="0.001" iyz="0.0" izz="0.002" />
    </inertial>
    <visual>
      <origin xyz="0 0 0" rpy="0 0 0" />
      <geometry>
        <mesh filename="package://agv_sim/meshes/C16_3D.stl" scale="0.001 0.001 0.001" />
      </geometry>
    </visual>
  </link>

  <!-- <joint name="safety_lidar_l_joint" type="fixed">
    <parent link="base_link" />
    <child link="safety_lidar_l" />
    <origin xyz="0.332 -0.442 -0.006" rpy="0 0 -0.7854" />
  </joint>

  <link name="safety_lidar_l">
    <inertial>
      <mass value="0.295"/>
      <inertia ixx="0.001" ixy="0.0" ixz="0.0" iyy="0.001" iyz="0.0" izz="0.002"/>
    </inertial>
    <visual>
      <origin xyz="0 0 0" rpy="-1.57 0 1.57" />
      <geometry>
        <mesh filename="package://agv_sim/meshes/2D_SAFETY_LIDAR.stl" scale = "0.001 0.001 0.001"/>
      </geometry>
    </visual>
  </link>

  <joint name="safety_lidar_r_joint" type="fixed">
    <parent link="base_link" />
    <child link="safety_lidar_r" />
    <origin xyz="0.332 0.442 -0.006" rpy="0 0 0.7854" />
  </joint>

  <link name="safety_lidar_r">
    <inertial>
      <mass value="0.295"/>
      <inertia ixx="0.001" ixy="0.0" ixz="0.0" iyy="0.001" iyz="0.0" izz="0.002"/>
    </inertial>
    <visual>
      <origin xyz="0 0 0" rpy="-1.57 0 1.56" />
      <geometry>
        <mesh filename="package://agv_sim/meshes/2D_SAFETY_LIDAR.stl" scale = "0.001 0.001 0.001"/>
      </geometry>
    </visual>
  </link>

  <joint name="safety_lidar_m_joint" type="fixed">
    <parent link="base_link" />
    <child link="safety_lidar_m" />
    <origin xyz="-0.863 0 -0.01" rpy="0 0 3.14" />
  </joint>

  <link name="safety_lidar_m">
    <inertial>
      <mass value="0.295"/>
      <inertia ixx="0.001" ixy="0.0" ixz="0.0" iyy="0.001" iyz="0.0" izz="0.002"/>
    </inertial>
    <visual>
      <origin xyz="0 0 0" rpy="-1.57 0 1.57" />
      <geometry>
        <mesh filename="package://agv_sim/meshes/2D_SAFETY_LIDAR.stl" scale = "0.001 0.001 0.001"/>
      </geometry>
    </visual>
  </link> -->
</robot>
