<?xml version="1.0"?>
<sdf version="1.5">
  <model name="agv1">

    <static>false</static>

    <pose>0.0 0.0 0.0 0.0 0.0 0.0</pose>

    <link name="base_footprint" />

    <joint name="base_joint" type="fixed">
      <parent>base_footprint</parent>
      <child>base_link</child>
      <pose>0.0 0.0 0.110 0 0 0</pose>
    </joint>

    <link name="base_link">

      <inertial>
        <pose>0.005 0.1475 0.492 0 0 0</pose>
        <inertia>
          <ixx>962.268</ixx>
          <ixy>-2.68</ixy>
          <ixz>13.459</ixz>
          <iyy>963.85</iyy>
          <iyz>81.387</iyz>
          <izz>482.35</izz>
        </inertia>
        <mass>2129.36</mass>
      </inertial>

      <collision name="base_collision">
        <pose>0 0 0.1 0 0 0</pose>
        <geometry>
          <mesh>
            <uri>model://agv_common/meshes/BODY.stl</uri>
            <!-- <scale>0.001 0.001 0.001</scale> -->
          </mesh>
        </geometry>
      </collision>

      <visual name="base_visual">
        <pose>0 0 0.1 0 0 0</pose>
        <geometry>
          <mesh>
            <uri>model://agv_common/meshes/BODY.stl</uri>
            <!-- <scale>0.001 0.001 0.001</scale> -->
          </mesh>
        </geometry>
      </visual>
    </link>

    <!-- <joint name="mast_joint" type="fixed">
      <parent>base_link</parent>
      <child>mast</child>
      <pose>0 0.631 1.975 0 0 0</pose>
    </joint>

    <link name="mast">

      <inertial>
        <pose>-0.003 0.914 0.841 0 0 0</pose>
        <inertia>
          <ixx>1122.28</ixx>
          <ixy>-0.195</ixy>
          <ixz>1.265</ixz>
          <iyy>1071.349</iyy>
          <iyz>-243.104</iyz>
          <izz>135.921</izz>
        </inertia>
        <mass>590.628</mass>
      </inertial>

      <collision name="mast_collision">
        <pose>0 0.631 1.975 0 0 0</pose>
        <geometry>
          <mesh>
            <uri>model://agv_common/meshes/MAST.stl</uri>
            <scale>0.001 0.001 0.001</scale>
          </mesh>
        </geometry>
      </collision>

      <visual name="mast_visual">
        <pose>0 0.631 1.975 0 0 0</pose>
        <geometry>
          <mesh>
            <uri>model://agv_common/meshes/MAST.stl</uri>
            <scale>0.001 0.001 0.001</scale>
          </mesh>
        </geometry>
      </visual>
    </link> -->

    <joint name="steering_joint" type="fixed">
      <parent>base_link</parent>
      <child>steering_part</child>
      <pose>0 -0.212 0.445 0 0 0</pose>
      <axis>
        <xyz>0 0 1</xyz>
      </axis>
    </joint>

    <link name="steering_part">

      <inertial>
        <pose>-0.0453 -0.2 0.445 0 0 0</pose>
        <inertia>
          <ixx>2.77</ixx>
          <ixy>0</ixy>
          <ixz>0.12</ixz>
          <iyy>2.81</iyy>
          <iyz>-0.11</iyz>
          <izz>0.92</izz>
        </inertia>
        <mass>85.056</mass>
      </inertial>

      <collision name="steering_part_collision">
        <pose>-0.0106 -0.202 0.448 0 0 0</pose>
        <geometry>
          <cylinder>
            <radius>0.175</radius>
            <length>0.158</length>
          </cylinder>
        </geometry>
        <surface>
          <friction>
            <ode>
              <mu>100000.0</mu>
              <mu2>100000.0</mu2>
              <fdir1>0 0 0</fdir1>
              <slip1>0.0</slip1>
              <slip2>0.0</slip2>
            </ode>
          </friction>
          <contact>
            <ode>
              <soft_cfm>0</soft_cfm>
              <soft_erp>0.2</soft_erp>
              <kp>5e+6</kp>
              <kd>1</kd>
              <max_vel>0.01</max_vel>
              <min_depth>0.001</min_depth>
            </ode>
          </contact>
        </surface>
      </collision>

      <visual name="steering_part_visual">
        <pose>-0.0456 -0.212 0.445 0 0 0</pose>
        <geometry>
          <mesh>
            <uri>model://agv_common/meshes/STEERING_PART_RE2.stl</uri>
          </mesh>
        </geometry>
      </visual>
    </link>

    <joint name="drive_wheel_joint" type="revolute">
      <parent>steering_part</parent>
      <child>drive_wheel</child>
      <pose>0.0175 -0.2 0.16 0 0 0</pose>
      <axis>
        <xyz>1 0 0</xyz>
      </axis>
    </joint>

    <link name="drive_wheel">

      <inertial>
        <pose>0.0175 -0.2 0.16 0 0 0</pose>
        <inertia>
          <ixx>0.166</ixx>
          <ixy>0.0</ixy>
          <ixz>0.0</ixz>
          <iyy>0.166</iyy>
          <iyz>0.0</iyz>
          <izz>0.166</izz>
        </inertia>
        <mass>21.755</mass>
      </inertial>

      <collision name="drive_wheel_collision">
        <pose>0.0175 -0.2 0.16 0 1.571 0</pose>
        <geometry>
          <cylinder>
            <radius>0.155</radius>
            <length>0.145</length>
          </cylinder>
        </geometry>
        <surface>
          <friction>
            <ode>
              <mu>100000.0</mu>
              <mu2>100000.0</mu2>
              <fdir1>0 0 0</fdir1>
              <slip1>0.0</slip1>
              <slip2>0.0</slip2>
            </ode>
          </friction>
          <contact>
            <ode>
              <soft_cfm>0</soft_cfm>
              <soft_erp>0.2</soft_erp>
              <kp>5e+6</kp>
              <kd>1</kd>
              <max_vel>1.5</max_vel>
              <min_depth>0.0005</min_depth>
            </ode>
          </contact>
        </surface>
      </collision>

      <visual name="drive_wheel_visual">
        <pose>0.0175 -0.2 0.16 0 0 0</pose>
        <geometry>
          <mesh>
            <uri>model://agv_common/meshes/DRIVE_WHEEL_RE2.stl</uri>
          </mesh>
        </geometry>
      </visual>
    </link>

    <joint name='front_wheel_l_joint' type='revolute'>
      <parent>base_link</parent>
      <child>front_wheel_l</child>
      <pose>-0.451 0.86 0.135 0 0 -1.571</pose>
      <axis>
        <xyz>0 -1 0</xyz>
      </axis>
    </joint>

    <link name="front_wheel_l">

      <inertial>
        <pose>-0.451 0.86 0.135 0 0 0</pose>

        <inertia>
          <ixx>0.066</ixx>
          <ixy>0.0</ixy>
          <ixz>0.0</ixz>
          <iyy>0.066</iyy>
          <iyz>0.0</iyz>
          <izz>0.066</izz>
        </inertia>
        <mass>16.096</mass>
      </inertial>

      <collision name='front_wheel_l_collision'>
        <pose>-0.451 0.86 0.135 0 1.571 0</pose>
        <geometry>
          <cylinder>
            <radius>0.125</radius>
            <length>0.114</length>
          </cylinder>
        </geometry>

        <surface>
          <contact>
            <ode>
              <soft_cfm>0</soft_cfm>
              <soft_erp>0.2</soft_erp>
              <kp>5e+6</kp>
              <kd>1</kd>
              <max_vel>1.5</max_vel>
              <min_depth>0.001</min_depth>
            </ode>
          </contact>
        </surface>
      </collision>

      <visual name="front_wheel_l_visual">
        <pose>-0.451 0.86 0.135 0 0 -1.571</pose>
        <geometry>
          <mesh>
            <uri>model://agv_common/meshes/FRONT_WHEEL_RE2.stl</uri>
          </mesh>
        </geometry>
      </visual>
    </link>

    <joint name='front_wheel_r_joint' type='revolute'>
      <parent>base_link</parent>
      <child>front_wheel_r</child>
      <pose>0.451 0.86 0.135 0 0 1.571</pose>
      <axis>
        <xyz>0 1 0</xyz>
      </axis>
    </joint>

    <link name='front_wheel_r'>
      <inertial>
        <pose>0.451 0.86 0.135 0 0 0</pose>
        <inertia>
          <ixx>0.066</ixx>
          <ixy>0.0</ixy>
          <ixz>0.0</ixz>
          <iyy>0.066</iyy>
          <iyz>0.0</iyz>
          <izz>0.066</izz>
        </inertia>
        <mass>16.096</mass>
      </inertial>
      <collision name='front_wheel_r_collision'>
        <pose>0.451 0.86 0.135 0 1.571 0</pose>
        <geometry>
          <cylinder>
            <radius>0.125</radius>
            <length>0.114</length>
          </cylinder>
        </geometry>
        <surface>
          <contact>
            <ode>
              <soft_cfm>0</soft_cfm>
              <soft_erp>0.2</soft_erp>
              <kp>5e+6</kp>
              <kd>1</kd>
              <max_vel>1.5</max_vel>
              <min_depth>0.001</min_depth>
            </ode>
          </contact>
        </surface>
      </collision>

      <visual name="front_wheel_r_visual">
        <pose>0.451 0.86 0.135 0 0 1.571</pose>
        <geometry>
          <mesh>
            <uri>model://agv_common/meshes/FRONT_WHEEL_RE2.stl</uri>
          </mesh>
        </geometry>
      </visual>
    </link>


    <joint name='slam_lidar_joint' type='fixed'>
      <parent>base_link</parent>
      <child>slam_lidar</child>
      <pose>0 -0.2 2.249 0 0 0</pose>
    </joint>

    <link name='slam_lidar'>
      <inertial>
        <pose>0 -0.2 2.249 0 0 0</pose>
        <inertia>
          <ixx>0.0</ixx>
          <ixy>0.0</ixy>
          <ixz>0.0</ixz>
          <iyy>0.0</iyy>
          <iyz>0.0</iyz>
          <izz>0.0</izz>
        </inertia>
        <mass>0.641</mass>
      </inertial>
      <!-- <collision name='slam_lidar_collision'>
        <pose>0 -0.2 2.249 0 0 0</pose>
        <geometry>
          <uri>model://agv_common/meshes/3D_SLAM_LIDAR.stl</uri>
          <scale>0.001 0.001 0.001</scale>
        </geometry>
      </collision> -->

      <visual name="slam_lidar_visual">
        <pose>0 -0.2 2.249 0 0 0</pose>
        <geometry>
          <mesh>
            <uri>model://agv_common/meshes/3D_SLAM_LIDAR.stl</uri>
            <scale>0.001 0.001 0.001</scale>
          </mesh>
        </geometry>
      </visual>

      <sensor name="3d_slam_lidar" type="ray">
        <always_on>true</always_on>
        <visualize>false</visualize>
        <pose>0 -0.2 2.339 0 0 0</pose>
        <update_rate>20</update_rate>
        <ray>
          <scan>
            <horizontal>
              <samples>360</samples>
              <resolution>1</resolution>
              <min_angle>-3.14</min_angle>
              <max_angle>3.14</max_angle>
            </horizontal>
            <vertical>
              <samples>16</samples>
              <resolution>1.0</resolution>
              <min_angle>-0.2793</min_angle>
              <max_angle>0.2443</max_angle>
            </vertical>
          </scan>
          <range>
            <min>0.1</min>
            <max>200</max>
            <resolution>0.03</resolution>
          </range>
          <noise>
            <type>gaussian</type>
            <mean>0.0</mean>
            <stddev>0.01</stddev>
          </noise>
        </ray>

        <plugin name="gazebo_ros_ray_sensor" filename="libgazebo_ros_ray_sensor.so">
          <topicName>/scan</topicName>
          <output_type>sensor_msgs/PointCloud2</output_type>
          <frameName>slam_lidar</frameName>
        </plugin>
      </sensor>

    </link>

    <joint name='safety_lidar_l_joint' type='fixed'>
      <parent>base_link</parent>
      <child>safety_lidar_l</child>
      <pose>-0.442 -0.332 0.104 0 0 0</pose>
    </joint>

    <link name='safety_lidar_l'>
      <inertial>
        <pose>-0.442 -0.332 0.104 0 0 0</pose>
        <inertia>
          <ixx>0.0</ixx>
          <ixy>0.0</ixy>
          <ixz>0.0</ixz>
          <iyy>0.0</iyy>
          <iyz>0.0</iyz>
          <izz>0.0</izz>
        </inertia>
        <mass>0.001</mass>
      </inertial>

      <visual name="safety_lidar_l_visual">
        <pose>-0.442 -0.332 0.104 -1.57 0 -0.7854</pose>
        <geometry>
          <mesh>
            <uri>model://agv_common/meshes/2D_SAFETY_LIDAR.stl</uri>
            <scale>0.001 0.001 0.001</scale>
          </mesh>
        </geometry>
      </visual>

      <sensor name="safety_lidar_l" type="ray">
        <always_on>true</always_on>
        <visualize>false</visualize>
        <pose>-0.442 -0.332 0.104 0 0 -2.3562</pose>
        <update_rate>10</update_rate>
        <ray>
          <scan>
            <horizontal>
              <samples>360</samples>
              <resolution>0.36</resolution>
              <min_angle>-0.7854</min_angle>
              <max_angle>0.7854</max_angle>
            </horizontal>
          </scan>
          <range>
            <min>0.1</min>
            <max>10</max>
            <resolution>0.001</resolution>
          </range>
          <noise>
            <type>gaussian</type>
            <mean>0.0</mean>
            <stddev>0.01</stddev>
          </noise>
        </ray>

        <plugin name="safety_lidar_l" filename="libgazebo_ros_ray_sensor.so">
          <topicName>/scan_s_l</topicName>
          <output_type>sensor_msgs/LaserScan</output_type>
          <frameName>safety_lidar_l</frameName>
        </plugin>
      </sensor>
    </link>

    <joint name='safety_lidar_r_joint' type='fixed'>
      <parent>base_link</parent>
      <child>safety_lidar_r</child>
      <pose>0.442 -0.332 0.104 0 0 0</pose>
    </joint>

    <link name='safety_lidar_r'>
      <inertial>
        <pose>0.442 -0.332 0.104 0 0 0</pose>
        <inertia>
          <ixx>0.0</ixx>
          <ixy>0.0</ixy>
          <ixz>0.0</ixz>
          <iyy>0.0</iyy>
          <iyz>0.0</iyz>
          <izz>0.0</izz>
        </inertia>
        <mass>0.001</mass>
      </inertial>

      <visual name="safety_lidar_r_visual">
        <pose>0.442 -0.332 0.104 -1.57 0 0.7854</pose>
        <geometry>
          <mesh>
            <uri>model://agv_common/meshes/2D_SAFETY_LIDAR.stl</uri>
            <scale>0.001 0.001 0.001</scale>
          </mesh>
        </geometry>
      </visual>

      <sensor name="safety_lidar_r" type="ray">
        <always_on>true</always_on>
        <visualize>false</visualize>
        <pose>0.442 -0.332 0.084 0 0 -0.7854</pose>
        <update_rate>10</update_rate>
        <ray>
          <scan>
            <horizontal>
              <samples>360</samples>
              <resolution>0.36</resolution>
              <min_angle>-0.7854</min_angle>
              <max_angle>0.7854</max_angle>
            </horizontal>
          </scan>
          <range>
            <min>0.1</min>
            <max>10</max>
            <resolution>0.001</resolution>
          </range>
          <noise>
            <type>gaussian</type>
            <mean>0.0</mean>
            <stddev>0.01</stddev>
          </noise>
        </ray>

        <plugin name="safety_lidar_r" filename="libgazebo_ros_ray_sensor.so">
          <topicName>/scan_s_r</topicName>
          <output_type>sensor_msgs/LaserScan</output_type>
          <frameName>safety_lidar_r</frameName>
        </plugin>
      </sensor>
    </link>

    <joint name='safety_lidar_m_joint' type='fixed'>
      <parent>base_link</parent>
      <child>safety_lidar_m</child>
      <pose>0 0.863 0.1 0 0 0</pose>
    </joint>

    <link name='safety_lidar_m'>
      <inertial>
        <pose>0 0.863 0.1 0 0 0</pose>
        <inertia>
          <ixx>0.0</ixx>
          <ixy>0.0</ixy>
          <ixz>0.0</ixz>
          <iyy>0.0</iyy>
          <iyz>0.0</iyz>
          <izz>0.0</izz>
        </inertia>
        <mass>0.001</mass>
      </inertial>

      <visual name="safety_lidar_m_visual">
        <pose>0 0.863 0.1 -1.57 0 3.14</pose>
        <geometry>
          <mesh>
            <uri>model://agv_common/meshes/2D_SAFETY_LIDAR.stl</uri>
            <scale>0.001 0.001 0.001</scale>
          </mesh>
        </geometry>
      </visual>

      <!-- sensor pose에서 원하는 만큼 회전 및 urdf파일의 joint를 이에 맞춰서 회전
       나머지 회전량은 비쥬얼에서 회전 -->
      <sensor name="safety_lidar_m" type="ray">
        <always_on>true</always_on>
        <visualize>false</visualize>
        <pose>0 0.863 0.1 0 0 1.57</pose>
        <update_rate>10</update_rate>
        <ray>
          <scan>
            <horizontal>
              <samples>360</samples>
              <resolution>0.36</resolution>
              <min_angle>-0.7854</min_angle>
              <max_angle>0.7854</max_angle>
            </horizontal>
          </scan>
          <range>
            <min>0.1</min>
            <max>10</max>
            <resolution>0.001</resolution>
          </range>
          <noise>
            <type>gaussian</type>
            <mean>0.0</mean>
            <stddev>0.01</stddev>
          </noise>
        </ray>

        <plugin name="safety_lidar_m" filename="libgazebo_ros_ray_sensor.so">
          <topicName>/scan_s_m</topicName>
          <output_type>sensor_msgs/LaserScan</output_type>
          <frameName>safety_lidar_m</frameName>
        </plugin>
      </sensor>
    </link>


    <plugin name="agv_drive" filename="libtricycle_drive_plugin.so">
      <max_wheel_acceleration>1.0</max_wheel_acceleration>
      <max_wheel_deceleration>1.0</max_wheel_deceleration>
      <!-- <max_wheel_speed_tolerance>5.0</max_wheel_speed_tolerance>
      <wheel_separation>1.0</wheel_separation> -->
    </plugin>

    <!-- <plugin name="agv_drive" filename="libgazebo_ros_tricycle_drive.so">

      <update_rate>30</update_rate>

      <steering_joint>steering_joint</steering_joint>
      <actuated_wheel_joint>drive_wheel_joint</actuated_wheel_joint>
      <encoder_wheel_left_joint>front_wheel_l_joint</encoder_wheel_left_joint>
      <encoder_wheel_right_joint>front_wheel_r_joint</encoder_wheel_right_joint>


      <wheel_separation>0.9</wheel_separation>
      <encoder_wheel_diameter>0.25</encoder_wheel_diameter>
      <actuated_wheel_diameter>0.31</actuated_wheel_diameter>


      <max_wheel_torque>100</max_wheel_torque>
      <max_wheel_acceleration>5.0</max_wheel_acceleration>
      <max_steering_speed>1.0</max_steering_speed>

      <publish_odom>true</publish_odom>
      <publish_wheel_tf>true</publish_wheel_tf>
      <publish_wheel_joint_state>true</publish_wheel_joint_state>

      <odometry_frame>odom</odometry_frame>
      <robot_base_frame>base_footprint</robot_base_frame>

    </plugin> -->
  </model>
</sdf>
